2016-11-26 13:26:17,977 - [INFO] [MainThread] (main:18) Program has started..
2016-11-26 13:26:17,978 - [INFO] [MainThread] (main:21) Scanning for devices...
2016-11-26 13:29:35,764 - [INFO] [MainThread] (main:18) Program has started..
2016-11-26 13:29:35,767 - [INFO] [MainThread] (main:21) Scanning for devices...
2016-11-26 13:29:37,364 - [INFO] [MainThread] (main:18) Program has started..
2016-11-26 13:29:37,366 - [INFO] [MainThread] (main:21) Scanning for devices...
2016-11-26 13:29:47,392 - [INFO] [MainThread] (main:25) Device a0:14:3d:a0:56:66 (public), RSSI=-58 dB
2016-11-26 13:29:47,393 - [INFO] [MainThread] (main:25) Device c4:be:84:28:89:4a (public), RSSI=-84 dB
2016-11-26 13:29:47,394 - [DEBUG] [MainThread] (main:47) Not connectable at the moment: c4:be:84:28:89:4a
2016-11-26 13:29:47,395 - [INFO] [MainThread] (main:25) Device a0:14:3d:a0:56:78 (public), RSSI=-59 dB
2016-11-26 13:29:47,396 - [INFO] [MainThread] (main:25) Device a0:14:3d:84:1b:34 (public), RSSI=-55 dB
2016-11-26 13:29:47,396 - [INFO] [MainThread] (main:28) Found device match...
2016-11-26 13:29:47,397 - [INFO] [MainThread] (main:38) Match: PARROT FLOWER
2016-11-26 13:29:47,398 - [INFO] [MainThread] (parrot_ble:136) Attempting to connect to sn1_parrot [a0:14:3d:84:1b:34]
2016-11-26 13:29:51,115 - [ERROR] [MainThread] (parrot_ble:146) Caught exception: Peripheral connection failed at /usr/local/lib/python3.4/dist-packages/bluepy/btle.py
Traceback (most recent call last):
  File "/home/pi/WSNApp/citas_dryad/dryad/parrot_ble.py", line 144, in setup_conn
    self.peripheral = Peripheral(self.device, "random")
  File "/usr/local/lib/python3.4/dist-packages/bluepy/btle.py", line 316, in __init__
    self.connect(deviceAddr.addr, deviceAddr.addrType, deviceAddr.iface)
  File "/usr/local/lib/python3.4/dist-packages/bluepy/btle.py", line 367, in connect
    "Failed to connect to peripheral %s, addr type: %s" % (addr, addrType))
bluepy.btle.BTLEException: Failed to connect to peripheral a0:14:3d:84:1b:34, addr type: public
2016-11-26 13:29:57,240 - [ERROR] [MainThread] (parrot_ble:146) Caught exception: Peripheral connection failed at /usr/local/lib/python3.4/dist-packages/bluepy/btle.py
Traceback (most recent call last):
  File "/home/pi/WSNApp/citas_dryad/dryad/parrot_ble.py", line 144, in setup_conn
    self.peripheral = Peripheral(self.device, "random")
  File "/usr/local/lib/python3.4/dist-packages/bluepy/btle.py", line 316, in __init__
    self.connect(deviceAddr.addr, deviceAddr.addrType, deviceAddr.iface)
  File "/usr/local/lib/python3.4/dist-packages/bluepy/btle.py", line 367, in connect
    "Failed to connect to peripheral %s, addr type: %s" % (addr, addrType))
bluepy.btle.BTLEException: Failed to connect to peripheral a0:14:3d:84:1b:34, addr type: public
2016-11-26 13:30:01,240 - [ERROR] [MainThread] (parrot_ble:146) Caught exception: Peripheral connection failed at /usr/local/lib/python3.4/dist-packages/bluepy/btle.py
Traceback (most recent call last):
  File "/home/pi/WSNApp/citas_dryad/dryad/parrot_ble.py", line 144, in setup_conn
    self.peripheral = Peripheral(self.device, "random")
  File "/usr/local/lib/python3.4/dist-packages/bluepy/btle.py", line 316, in __init__
    self.connect(deviceAddr.addr, deviceAddr.addrType, deviceAddr.iface)
  File "/usr/local/lib/python3.4/dist-packages/bluepy/btle.py", line 367, in connect
    "Failed to connect to peripheral %s, addr type: %s" % (addr, addrType))
bluepy.btle.BTLEException: Failed to connect to peripheral a0:14:3d:84:1b:34, addr type: public
2016-11-26 13:30:05,409 - [INFO] [MainThread] (parrot_ble:147) Connected.
2016-11-26 13:30:08,884 - [INFO] [MainThread] (parrot_ble:91) Starting sensor readings...
2016-11-26 13:30:10,775 - [INFO] [MainThread] (main:25) Device a0:14:3d:a0:61:a1 (public), RSSI=-54 dB
2016-11-26 13:30:10,783 - [INFO] [MainThread] (main:55) MERGED: defaultdict(<class 'dict'>, {'sn1': {'CAL_DLI': 0.13590790331363678, 'CAL_EA': 1.3081607818603516, 'CAL_ECB': 0.0, 'VWC': 0.0, 'PF_ADDR': 'a0:14:3d:84:1b:34', 'CAL_VWC': 0.0, 'BATTERY': 93, 'PF_TIMESTAMP': '2016-11-26 13:30:10', 'CAL_AIR_TEMP': 25.654172897338867, 'CAL_EC_POROUS': -0.0, 'SOIL_TEMP': 25.388209095000004, 'SUNLIGHT': 0.12969122911021727, 'AIR_TEMP': 24.71417088, 'SOIL_EC': 0.0}})
2016-11-26 13:30:12,088 - [INFO] [MainThread] (main:18) Program has started..
2016-11-26 13:30:12,090 - [INFO] [MainThread] (main:21) Scanning for devices...
2016-11-26 13:30:22,114 - [INFO] [MainThread] (main:25) Device c4:be:84:28:89:4a (public), RSSI=-91 dB
2016-11-26 13:30:22,115 - [INFO] [MainThread] (main:28) Found device match...
2016-11-26 13:30:22,116 - [INFO] [MainThread] (main:32) Match: BLUNO
2016-11-26 13:30:22,117 - [INFO] [MainThread] (bluno_ble:128) Attempting to connect to sn1_bluno [c4:be:84:28:89:4a]
2016-11-26 13:30:23,027 - [INFO] [MainThread] (bluno_ble:140) Connected.
2016-11-26 13:30:24,102 - [INFO] [MainThread] (bluno_ble:74) Bluno: Deployed
2016-11-26 13:30:27,268 - [INFO] [MainThread] (main:25) Device a0:14:3d:a0:61:a1 (public), RSSI=-56 dB
2016-11-26 13:30:27,269 - [INFO] [MainThread] (main:25) Device a0:14:3d:84:1b:34 (public), RSSI=-54 dB
2016-11-26 13:30:27,270 - [INFO] [MainThread] (main:28) Found device match...
2016-11-26 13:30:27,271 - [INFO] [MainThread] (main:38) Match: PARROT FLOWER
2016-11-26 13:30:27,272 - [INFO] [MainThread] (parrot_ble:136) Attempting to connect to sn1_parrot [a0:14:3d:84:1b:34]
2016-11-26 13:30:30,989 - [ERROR] [MainThread] (parrot_ble:146) Caught exception: Peripheral connection failed at /usr/local/lib/python3.4/dist-packages/bluepy/btle.py
Traceback (most recent call last):
  File "/home/pi/WSNApp/citas_dryad/dryad/parrot_ble.py", line 144, in setup_conn
    self.peripheral = Peripheral(self.device, "random")
  File "/usr/local/lib/python3.4/dist-packages/bluepy/btle.py", line 316, in __init__
    self.connect(deviceAddr.addr, deviceAddr.addrType, deviceAddr.iface)
  File "/usr/local/lib/python3.4/dist-packages/bluepy/btle.py", line 367, in connect
    "Failed to connect to peripheral %s, addr type: %s" % (addr, addrType))
bluepy.btle.BTLEException: Failed to connect to peripheral a0:14:3d:84:1b:34, addr type: public
2016-11-26 13:30:34,989 - [ERROR] [MainThread] (parrot_ble:146) Caught exception: Peripheral connection failed at /usr/local/lib/python3.4/dist-packages/bluepy/btle.py
Traceback (most recent call last):
  File "/home/pi/WSNApp/citas_dryad/dryad/parrot_ble.py", line 144, in setup_conn
    self.peripheral = Peripheral(self.device, "random")
  File "/usr/local/lib/python3.4/dist-packages/bluepy/btle.py", line 316, in __init__
    self.connect(deviceAddr.addr, deviceAddr.addrType, deviceAddr.iface)
  File "/usr/local/lib/python3.4/dist-packages/bluepy/btle.py", line 367, in connect
    "Failed to connect to peripheral %s, addr type: %s" % (addr, addrType))
bluepy.btle.BTLEException: Failed to connect to peripheral a0:14:3d:84:1b:34, addr type: public
2016-11-26 13:30:40,989 - [ERROR] [MainThread] (parrot_ble:146) Caught exception: Peripheral connection failed at /usr/local/lib/python3.4/dist-packages/bluepy/btle.py
Traceback (most recent call last):
  File "/home/pi/WSNApp/citas_dryad/dryad/parrot_ble.py", line 144, in setup_conn
    self.peripheral = Peripheral(self.device, "random")
  File "/usr/local/lib/python3.4/dist-packages/bluepy/btle.py", line 316, in __init__
    self.connect(deviceAddr.addr, deviceAddr.addrType, deviceAddr.iface)
  File "/usr/local/lib/python3.4/dist-packages/bluepy/btle.py", line 367, in connect
    "Failed to connect to peripheral %s, addr type: %s" % (addr, addrType))
bluepy.btle.BTLEException: Failed to connect to peripheral a0:14:3d:84:1b:34, addr type: public
2016-11-26 13:30:44,989 - [ERROR] [MainThread] (parrot_ble:146) Caught exception: Peripheral connection failed at /usr/local/lib/python3.4/dist-packages/bluepy/btle.py
Traceback (most recent call last):
  File "/home/pi/WSNApp/citas_dryad/dryad/parrot_ble.py", line 144, in setup_conn
    self.peripheral = Peripheral(self.device, "random")
  File "/usr/local/lib/python3.4/dist-packages/bluepy/btle.py", line 316, in __init__
    self.connect(deviceAddr.addr, deviceAddr.addrType, deviceAddr.iface)
  File "/usr/local/lib/python3.4/dist-packages/bluepy/btle.py", line 367, in connect
    "Failed to connect to peripheral %s, addr type: %s" % (addr, addrType))
bluepy.btle.BTLEException: Failed to connect to peripheral a0:14:3d:84:1b:34, addr type: public
2016-11-26 13:30:48,989 - [ERROR] [MainThread] (parrot_ble:146) Caught exception: Peripheral connection failed at /usr/local/lib/python3.4/dist-packages/bluepy/btle.py
Traceback (most recent call last):
  File "/home/pi/WSNApp/citas_dryad/dryad/parrot_ble.py", line 144, in setup_conn
    self.peripheral = Peripheral(self.device, "random")
  File "/usr/local/lib/python3.4/dist-packages/bluepy/btle.py", line 316, in __init__
    self.connect(deviceAddr.addr, deviceAddr.addrType, deviceAddr.iface)
  File "/usr/local/lib/python3.4/dist-packages/bluepy/btle.py", line 367, in connect
    "Failed to connect to peripheral %s, addr type: %s" % (addr, addrType))
bluepy.btle.BTLEException: Failed to connect to peripheral a0:14:3d:84:1b:34, addr type: public
2016-11-26 13:30:55,226 - [INFO] [MainThread] (parrot_ble:147) Connected.
2016-11-26 13:30:58,799 - [INFO] [MainThread] (parrot_ble:91) Starting sensor readings...
2016-11-26 13:31:00,692 - [INFO] [MainThread] (main:25) Device a0:14:3d:a0:56:66 (public), RSSI=-54 dB
2016-11-26 13:31:00,693 - [INFO] [MainThread] (main:25) Device a0:14:3d:a0:56:78 (public), RSSI=-60 dB
2016-11-26 13:31:00,694 - [INFO] [MainThread] (main:55) MERGED: defaultdict(<class 'dict'>, {'sn1': {'PF_TIMESTAMP': '2016-11-26 13:31:00', 'CAL_EA': 1.2658042907714844, 'PF_ADDR': 'a0:14:3d:84:1b:34', 'BATTERY': 93, 'BL_TIMESTAMP': '2016-11-26 13:30:27', 'CAL_AIR_TEMP': 25.383440017700195, 'CAL_ECB': 0.0, 'CAL_EC_POROUS': -0.0, 'BL_ADDR': 'c4:be:84:28:89:4a', 'PH': 8.96453, 'SUNLIGHT': 0.12969122911021727, 'CAL_VWC': 0.0, 'SOIL_EC': 0.0, 'AIR_TEMP': 24.533757373440007, 'SOIL_TEMP': 25.388209095000004, 'VWC': 0.0, 'CAL_DLI': 0.13590790331363678}})
